Workbook

Sheet Readme
A1: ADC Performance Survey 1997-2025
A2: Boris Murmann, University of Hawaii, bmurmann@hawaii.edu
A4: The purpose of this data collection is to help identify trends and limits in the power efficiency of A/D converters. In an ideal world, everyone would use the same metrics and conditions to specify the power dissipation, bandwidth and resolution of their designs. Unfortunately, in this world, different authors use different metrics and interpretations. Having said this, it is clear that the tabulated data in this document must be read with a grain of salt. Clearly, each data point could be shifted up/down, left/right based on your very own interpretation. Note, however, that this will have little impact on the overall objective, i.e. track general trends and performance envelopes.
A6: For use in publications and presentations please cite this data collection as follows:
A7: B. Murmann, "ADC Performance Survey 1997-2024," [Online]. Available: https://github.com/bmurmann/ADC-survey.
A9: Notes on the primary (raw data) columns:
A11: Power (P) - Taken as specified by the authors. Sometimes this number includes power for clocks, references, etc.; sometimes it doesn't. For delta-sigma modulators, the power for the decimation filter is not included. This is fair since the Nyquist converter data also does not include any power typically needed for anti-alias filtering.
A12: fsnyq - Nyquist sampling rate, equal to the sampling rate (fs) divided by the oversampling ratio (OSR). Note that for a complex delta-sigma modulator, the OSR is given by 2*fs/fsnyq.
A13: SNDR_hf, SNR, THD, SFDR are tabulated as the values measured near fsnyq/2 for a Nyquist converter. When this data was not available, data for lower input frequencies is used instead. Fortunately, in recent years, most Nyquist converters are properly evaluated up to fsnyq/2. Only older data points (before ~2003) tend to suffer from "low frequency only" issues. Multi-GHz converters tend to roll off for frequencies much lower than fs/2. For these designs, the SNDR at the highest reasonable/usable fin is used (example: ISSCC 2003, paper 18.2., fs=20GHz, SNDR measured at fin=6GHz).
A14: fin_hf - This is the frequency at which SNDR_hf was measured. For Nyquist ADCs, fin_hf is typically taken equal to fsnyq/2 where justified, i.e. the listed SNDR is also measured at fsnyq/2. Exceptions include designs that roll off below Nyquist (example: ISSCC 2003, paper 18.2., fs=20GHz, SNDR measured up to fin=6GHz ==>fin_hf=6GHz). This column is therefore useful primarily to capture these exceptions, which also tend to be the designs that push the envelope on aperture bandwidth. (Note: this column was called "BW_plot" in earlier versions of this survey.
A15: SNDR_lf - SNDR measured at low input frequencies. The sinusoidal SNDR near Nyquist (SNDR_hf) is not always a meaningful metric. Consider for example recent high-speed converters that are designed for broadband inputs (high speed links, cable TV tuners, etc.), where the signal power is spread rather than being concentrated in one tone. In this case, the low frequency SNDR is actually a better (less pessimistic, perhaps somewhat optimistic) number to consider for system design.
A16: DR is the measured "instantaneous dynamic range" of the converter, i.e. this metric does not contain any extra dBs obtained through variable gain.
... A96: 20250721: Update VLSI 2025

Sheet ISSCC
A1: YEAR | B1: ID | C1: TYPE | D1: ARCHITECTURE | E1: TECHNOLOGY | F1: TITLE | G1: ABSTRACT | H1: AUTHORS | I1: DOI | J1: LINK | K1: COMMENTS | L1: VSUP1 [V] | M1: VSUP2 [V] | N1: VSUP3 [V] | O1: Csamp [pF] | P1: AREA [mm^2] | Q1: SNDR_lf [dB] | R1: fin_hf [Hz] | S1: SNDR_hf [dB] | T1: SNR [dB] | U1: DR [dB] | V1: -THD [dB] | W1: SFDR [dB] | X1: SNDR_plot [dB] | Y1: P [W] | Z1: fs [Hz] | AA1: OSR | AB1: fsnyq [Hz] | AC1: fcenter [Hz] | AD1: P/fsnyq [pJ] | AE1: FOMW_lf [fJ/conv-step] | AF1: FOMW_hf [fJ/conv-step] | AG1: FOMS_lf [dB] | AH1: FOMS_hf [dB] | AI1: FOMW_hf/fsnyq | AJ1: FOMS,hf+10log(fsnyq)
A2: 1997 | B2: 8.1 | C2: NQ | D2: SAR | E2: 1 | F2: A MOSFET-only, 10 b, 200 ksample/s A/D converter capable of 12 b untrimmed linearity | G2: The linearity of a successive approximation (SA) A/D converter is typically limited by its passive network. Published converters based on capacitive arrays or resistive ladders are limited to around 10 b if no trimming or calibration is used. Although static measurements show that MOS transistors are capable of excellent matching, few MOSFET-only converters achieved more than 10 b accuracy without self-calibration. This A/D converter adopts the current division ladder network based on MOSFETs. Extensive measurements on the MOSFET ladders with different resolutions and geometry establish the achievable linearity | H2: C. Hammerschmied, Q. Huang | I2: 10.1109/ISSCC.1997.585301 | J2: =IF(I2<>"?", HYPERLINK(CONCATENATE("https://doi.org/",I2)), "") -> https://doi.org/10.1109/ISSCC.1997.585301 | L2: 5 | P2: 2.155 | R2: =Z2/2 -> 100000 | S2: =9.1*6.02+1.76 -> 56.542 | X2: =+IF(ISNUMBER($S2),$S2,MIN($V2,$T2,$U2,$W2)) -> 56.542 | Y2: =0.0024*5 -> 0.012 | Z2: 200000 | AA2: 1 | AB2: =Z2/AA2 -> 200000 | AD2: =Y2/AB2*1000000000000 -> 60000 | AE2: =IF(ISNUMBER($Q2), $AD2*1000/2^(($Q2-1.76)/6.02), "") | AF2: =$AD2*1000/2^(($X2-1.76)/6.02) -> 109339.8 | AG2: =IF(ISNUMBER($Q2), $Q2+10*LOG10($AB2/2/$Y2), "") | AH2: =$X2+10*LOG10($AB2/2/$Y2) -> 125.75019 | AI2: =AF2/AB2 -> 0.54669902 | AJ2: =AH2+10*LOG10(AB2) -> 178.76049
A3: 1997 | B3: 8.2 | C3: NQ | D3: Folding | E3: 1.00 BiCMOS | F3: A 12 b 50 M sample/s cascaded folding and interpolating ADC | G3: The architecture of this 12 b ADC is based on a three-stage conversion, using cascaded folding and interpolating techniques. Compared to other multi-stage ADC architectures, folding and interpolating ADCs are based on non-linear analog pre-processing. This architecture is an attractive solution for high-resolution ADCs, as extremely linear circuit topologies are not required. To increase the resolution of folding and interpolating ADCs above the published 8 b examples, without raising the number of parallel input stages or the number of comparators in the fine-comparator, a cascaded folding and interpolating architecture is introduced. The ADC achieves 64 dB signal-to-noise ratio (SNR) and 75 dB spurious-free dynamic range (SFDR), while quantizing a 15 MHz full-scale input signal at 50 MSample/s. The 7.0 mm² ADC is fabricated in a 13 GHz, 1 μm BiCMOS process and dissipates 300 mW from a single 5.0 V supply. The device is mounted in a standard 44-pin plastic package | H3: P. Vorenkamp, R. Roovers | I3: 10.1109/ISSCC.1997.585303 | J3: =IF(I3<>"?", HYPERLINK(CONCATENATE("https://doi.org/",I3)), "") -> https://doi.org/10.1109/ISSCC.1997.585303 | L3: 5 | P3: 7 | R3: =Z3/2 -> 25000000 | T3: 64 | W3: 75 | X3: =+IF(ISNUMBER($S3),$S3,MIN($V3,$T3,$U3,$W3)) -> 64 | Y3: 0.3 | Z3: 50000000 | AA3: 1 | AB3: =Z3/AA3 -> 50000000 | AD3: =Y3/AB3*1000000000000 -> 6000 | AE3: =IF(ISNUMBER($Q3), $AD3*1000/2^(($Q3-1.76)/6.02), "") | AF3: =$AD3*1000/2^(($X3-1.76)/6.02) -> 4632.7742 | AG3: =IF(ISNUMBER($Q3), $Q3+10*LOG10($AB3/2/$Y3), "") | AH3: =$X3+10*LOG10($AB3/2/$Y3) -> 143.20819 | AI3: =AF3/AB3 -> 9.2655483e-05 | AJ3: =AH3+10*LOG10(AB3) -> 220.19789
A4: 1997 | B4: 8.3 | C4: NQ | D4: Folding | E4: 0.5 | F4: A 170 mW 10 b 50 Msample/s CMOS ADC in 1 mm² | G4: This 10 b AD-converter at a sample rate of 5O MSample/s, embedded in 50mm² of digital circuitry, shows 8.7 effective bits. A straight flash-architecture would need 1023 accurate fast comparators. With a 2 V input range, a comparator offset voltage of no more than 1 mV can be tolerated. Taking into account that the 1 mV is a 3-6 sigma value, leads to a large chip. If, however, the signals to the comparator are amplified before the critical decision, simple small comparators would suffice. To cope with the dynamic offset caused by the clocking and latch action of the comparator itself, the architecture must tolerate comparator offsets of up to 60-80 mV. Hence, a gain of at least 30 is necessary. A single amplifier however, could not handle this, as the input range of 2 V would be amplified to 60 V. The approach here is to use a distributed amplifier | H4: K. Bult, A. Buchwald, J. Laskowski | I4: 10.1109/ISSCC.1997.585303 | J4: =IF(I4<>"?", HYPERLINK(CONCATENATE("https://doi.org/",I4)), "") -> https://doi.org/10.1109/ISSCC.1997.585303 | L4: 5 | P4: 1 | R4: =Z4/2 -> 25000000 | S4: =1.76+8.6*6.02 -> 53.532 | X4: =+IF(ISNUMBER($S4),$S4,MIN($V4,$T4,$U4,$W4)) -> 53.532 | Y4: 0.17 | Z4: 50000000 | AA4: 1 | AB4: =Z4/AA4 -> 50000000 | AD4: =Y4/AB4*1000000000000 -> 3400 | AE4: =IF(ISNUMBER($Q4), $AD4*1000/2^(($Q4-1.76)/6.02), "") | AF4: =$AD4*1000/2^(($X4-1.76)/6.02) -> 8762.3572 | AG4: =IF(ISNUMBER($Q4), $Q4+10*LOG10($AB4/2/$Y4), "") | AH4: =$X4+10*LOG10($AB4/2/$Y4) -> 135.20691 | AI4: =AF4/AB4 -> 0.00017524714 | AJ4: =AH4+10*LOG10(AB4) -> 212.19661
A5: 1997 | B5: 8.4 | C5: NQ | D5: Two-step | E5: Bipolar | F5: A 12 b 128 MSample/s ADC with 0.05 LSB DNL | G5: This analog-to-digital converter uses integrated dither, dynamic element matching, and output data scrambling to achieve SFDR of 85dB and DNL below 0.05LSB at l28MSample/s. This compares to about 0.5LSB DNL for slower 12b converters. The basic two-step flash architecture is shown. The ±0.25V input is amplified to ±1V and held in the track-and-hold circuit when the input clock rises. The 32 comparators in ADC1 produce an approximation that switches the 32 matched current sources in the main DAC. The residue is formed and amplified in the summer to ±0.5V and is converted by ADC2, an 8b folding-and-interpolating flash ADC. To allow low clock rates, there is no analog pipelining, and all analog settling from the track-to-hold transition to latching the result in ADC2 takes only 4.4ns. The ADC1 and ADC2 results added together form the 12b output. The total signal-to-data-output delay is slightly more than two cycles due to digital pipelining | H5: R. Jewett, K. Poulton, K.-C. Hsieh, J. Doernberg | I5: 10.1109/ISSCC.1997.585305 | J5: =IF(I5<>"?", HYPERLINK(CONCATENATE("https://doi.org/",I5)), "") -> https://doi.org/10.1109/ISSCC.1997.585305 | L5: 5 | N5: -4.5 | R5: =Z5/2 -> 64000000 | T5: 58.4 | X5: =+IF(ISNUMBER($S5),$S5,MIN($V5,$T5,$U5,$W5)) -> 58.4 | Y5: 5.7 | Z5: 128000000 | AA5: 1 | AB5: =Z5/AA5 -> 128000000 | AD5: =Y5/AB5*1000000000000 -> 44531.25 | AE5: =IF(ISNUMBER($Q5), $AD5*1000/2^(($Q5-1.76)/6.02), "") | AF5: =$AD5*1000/2^(($X5-1.76)/6.02) -> 65521.324 | AG5: =IF(ISNUMBER($Q5), $Q5+10*LOG10($AB5/2/$Y5), "") | AH5: =$X5+10*LOG10($AB5/2/$Y5) -> 128.90305 | AI5: =AF5/AB5 -> 0.00051188535 | AJ5: =AH5+10*LOG10(AB5) -> 209.97515
A6: 1997 | B6: 8.8 | C6: NQ | D6: Pipe | E6: 1.4 | F6: A 15 b 5 MSample/s low-spurious CMOS ADC | G6: This 15b CMOS ADC at 5MSample/s has four stages with 5, 5, 5, and 6b each. The number of bits resolved per stage is set higher to achieve the same resolution with less accurate components. Resolving more bits per stage greatly simplifies op amp design and reduces the initial capacitor matching requirement. Furthermore, residue amplifiers with low feedback factors are less sensitive to summing-node parasitics. The first two 5b stages are calibrated using the remaining part of the ADC. Two stages are selected for calibration. The gain ofthe 5b residue amplifier is set to 16 to make room for digital correction. After digital correction, the chip has an 18b output. Performance up to 16b level can be tested after removing 2 LSBs corrupted by digital processing. System partitioning and multi-stage calibration solve two fundamental problems of capacitor matching and finite opamp gain | H6: S.-U. Kwak, B.-S. Song, K. Bacrania | I6: 10.1109/ISSCC.1997.585309 | J6: =IF(I6<>"?", HYPERLINK(CONCATENATE("https://doi.org/",I6)), "") -> https://doi.org/10.1109/ISSCC.1997.585309 | K6: Power includes digital (addtl. 70mW) | L6: 5 | P6: 27.28 | R6: =Z6/2 -> 2500000 | S6: 84.9 | T6: 86.9 | W6: 93 | X6: =+IF(ISNUMBER($S6),$S6,MIN($V6,$T6,$U6,$W6)) -> 84.9 | Y6: 0.13 | Z6: 5000000 | AA6: 1 | AB6: =Z6/AA6 -> 5000000 | AD6: =Y6/AB6*1000000000000 -> 26000 | AE6: =IF(ISNUMBER($Q6), $AD6*1000/2^(($Q6-1.76)/6.02), "") | AF6: =$AD6*1000/2^(($X6-1.76)/6.02) -> 1809.5021 | AG6: =IF(ISNUMBER($Q6), $Q6+10*LOG10($AB6/2/$Y6), "") | AH6: =$X6+10*LOG10($AB6/2/$Y6) -> 157.73997 | AI6: =AF6/AB6 -> 0.00036190042 | AJ6: =AH6+10*LOG10(AB6) -> 224.72967
A7: 1997 | B7: 13.1 | C7: OS | D7: SDSC, Pipe | E7: 0.6 | F7: A 16b ΣΔ pipeline ADC with 2.5 MHz output data-rate | G7: A 16b 2.5 MHz A/D converter in 0.6 μm CMOS addresses the need for wide dynamic range A/D converters with bandwidths in excess of 1 MHz in multi-tone communication. This A/D converter combines the advantages of ΣΔ and pipeline A/D conversion techniques to provide wide dynamic range at a low-oversampling ratio. The device operates at a 20 MHz clock rate, 2.5 MHz output rate (8× oversampling), and provides 89 dB SNR over a 1.25 MHz input bandwidth | H7: T.L Brooks, D.H. Robertson, D.F. Kelly, A. Del Muro, S.W. Harston | I7: 10.1109/ISSCC.1997.585335 | J7: =IF(I7<>"?", HYPERLINK(CONCATENATE("https://doi.org/",I7)), "") -> https://doi.org/10.1109/ISSCC.1997.585335 | P7: 31.8 | R7: 1250000 | T7: 89 | W7: 97 | X7: =+IF(ISNUMBER($S7),$S7,MIN($V7,$T7,$U7,$W7)) -> 89 | Y7: 0.55 | Z7: 20000000 | AA7: 8 | AB7: =Z7/AA7 -> 2500000 | AD7: =Y7/AB7*1000000000000 -> 220000 | AE7: =IF(ISNUMBER($Q7), $AD7*1000/2^(($Q7-1.76)/6.02), "") | AF7: =$AD7*1000/2^(($X7-1.76)/6.02) -> 9549.6618 | AG7: =IF(ISNUMBER($Q7), $Q7+10*LOG10($AB7/2/$Y7), "") | AH7: =$X7+10*LOG10($AB7/2/$Y7) -> 152.56547 | AI7: =AF7/AB7 -> 0.0038198647 | AJ7: =AH7+10*LOG10(AB7) -> 216.54487
A8: 1997 | B8: 13.2 | C8: OS | D8: SDSC | E8: 0.5 | F8: Low-voltage double-sampled ΣΔ converters | G8: In theory, double-sampling in second-order ΣΔ analog-to-digital converters (ADC) can enhance the signal-to-noise ratio (SNR) by 15 dB. In practice however, the SNR performance is usually severely degraded because of mismatches occurring in switched-capacitors (SC). This paper introduces a simple method to solve this problem. Regarding ΣΔ digital-to-analog converters (DAC), in addition to double-sampling, the accompanying use of internal decimation helps to relax the bandwidth requirements of the opamps. Both circuitries are to be operational to supply voltages as low as 1.5 V by using clock bootstrapping. Chip implementation is in double-poly, 2-metal technology featuring 0.5 μm minimum channel lengths | H8: Senderowicz, D.; Nicollini, G.; Pernici, S.; Nagari, A.; Confalonieri, P.; Dallavalle, C. | I8: 10.1109/ISSCC.1997.585336 | J8: =IF(I8<>"?", HYPERLINK(CONCATENATE("https://doi.org/",I8)), "") -> https://doi.org/10.1109/ISSCC.1997.585336 | L8: 1.5 | P8: 0.39 | R8: 1000 | S8: 81 | U8: 88 | X8: =+IF(ISNUMBER($S8),$S8,MIN($V8,$T8,$U8,$W8)) -> 81 | Y8: 0.00055 | Z8: 1000000 | AA8: 500 | AB8: =Z8/AA8 -> 2000 | AD8: =Y8/AB8*1000000000000 -> 275000 | AE8: =IF(ISNUMBER($Q8), $AD8*1000/2^(($Q8-1.76)/6.02), "") | AF8: =$AD8*1000/2^(($X8-1.76)/6.02) -> 29987.335 | AG8: =IF(ISNUMBER($Q8), $Q8+10*LOG10($AB8/2/$Y8), "") | AH8: =$X8+10*LOG10($AB8/2/$Y8) -> 143.59637 | AI8: =AF8/AB8 -> 14.993667 | AJ8: =AH8+10*LOG10(AB8) -> 176.60667
A9: 1997 | B9: 13.3 | C9: OS | D9: SDSC, TI, BP | E9: 0.6 | F9: A two-path bandpass ΣΔ modulator for digital IF extraction at 20 MHz | G9: There is expanding interest in the possibility of moving the intermediate frequency (IF) signal processing in radio receivers and radio test equipment from the analog domain into the digital domain. Digitization of IF processing confers several important advantages, including greater reliability, potentially lower power consumption, and improved performance as technology scales. Unfortunately, as analog signal processing is eliminated and the A/D conversion is moved away from baseband, the signal that must be digitized has a larger dynamic range, and the converter must operate at a higher sampling rate. This work introduces a two-path, switched-capacitor architecture for a bandpass ΣΔ modulator that is suited to digitizing narrowband radio signals with large dynamic range. A fourth-order bandpass modulator is implemented in a standard 0.6 μm, single-poly, triple-metal CMOS process. Operating from a single 3.3 V supply, the modulator digitizes a 200 kHz signal centered at an IF of 20 MHz with an extrapolated dynamic range of 75 dB | H9: Ong, A.K.; Wooley, B.A. | I9: 10.1109/ISSCC.1997.585337 | J9: =IF(I9<>"?", HYPERLINK(CONCATENATE("https://doi.org/",I9)), "") -> https://doi.org/10.1109/ISSCC.1997.585337 | K9: IF=20MHz | L9: 3.3 | P9: 2.73 | R9: 200000 | S9: 75 | U9: 75 | X9: =+IF(ISNUMBER($S9),$S9,MIN($V9,$T9,$U9,$W9)) -> 75 | Y9: 0.072 | Z9: 40000000 | AA9: 100 | AB9: =Z9/AA9 -> 400000 | AC9: 20000000 | AD9: =Y9/AB9*1000000000000 -> 180000 | AE9: =IF(ISNUMBER($Q9), $AD9*1000/2^(($Q9-1.76)/6.02), "") | AF9: =$AD9*1000/2^(($X9-1.76)/6.02) -> 39165.852 | AG9: =IF(ISNUMBER($Q9), $Q9+10*LOG10($AB9/2/$Y9), "") | AH9: =$X9+10*LOG10($AB9/2/$Y9) -> 139.43697 | AI9: =AF9/AB9 -> 0.097914629 | AJ9: =AH9+10*LOG10(AB9) -> 195.45757
A10: 1997 | B10: 13.4 | C10: OS | D10: SDCT, BP | E10: HBT | F10: A bandpass ΣΔ modulator with 92 dB SNR and center frequency continuously programmable from 0 to 70 MHz | G10: Use of a bandpass ΣΔ modulator permits direct conversion of an analog signal to digital form at IF frequencies. This allows the ADC to be moved closer to the receiver front end. Moving the digital interface closer to the antenna reduces receiver analog circuit complexity, eliminates DC-offset cancellation, inphase/quadrature (I/Q) gain calibration, dual I/Q mixers and improves system robustness as mixing is in the digital domain. This second-order bandpass ΣΔ modulator is targeted for an airborne radar system but is also expected to find use in a variety of communications applications. Measurements yield signal to noise+distortion ratio (SNR) from 92 dB (15 b) in narrowband ( 366 kHz) to 44 dB (7 b) in broadband (62.6 MHz) about a center frequency of 55.5 MHz. Modulator sampling rate is 4 GHz and it is implemented in AlInAs-InGaAs HBT technology. The performance represents an improvement of approximately a factor of 10 in bandwidth, resolution and center frequency over other reported bandpass modulators | H10: Raghavan, G.; Jensen, J.F.; Walden, R.H.; Posey, W.P. | I10: 10.1109/ISSCC.1997.585338 | J10: =IF(I10<>"?", HYPERLINK(CONCATENATE("https://doi.org/",I10)), "") -> https://doi.org/10.1109/ISSCC.1997.585338 | K10: Data taken for max. BW, IF=55MHz | P10: 0.5625 | R10: 62600000 | S10: 44.1 | X10: =+IF(ISNUMBER($S10),$S10,MIN($V10,$T10,$U10,$W10)) -> 44.1 | Y10: 1.4 | Z10: 4000000000 | AA10: 31.948882 | AB10: =Z10/AA10 -> 125200000 | AC10: 55000000 | AD10: =Y10/AB10*1000000000000 -> 11182.109 | AE10: =IF(ISNUMBER($Q10), $AD10*1000/2^(($Q10-1.76)/6.02), "") | AF10: =$AD10*1000/2^(($X10-1.76)/6.02) -> 85371.466 | AG10: =IF(ISNUMBER($Q10), $Q10+10*LOG10($AB10/2/$Y10), "") | AH10: =$X10+10*LOG10($AB10/2/$Y10) -> 120.60446 | AI10: =AF10/AB10 -> 0.00068188072 | AJ10: =AH10+10*LOG10(AB10) -> 201.58051
A11: 1997 | B11: 13.5 | C11: OS | D11: SDCT, Complex, BP | E11: 0.8 | F11: A quadrature bandpass ΣΔ modulator for digital radio | G11: In a bandpass ΣΔ modulator, bandpass filtering and feedback around a low-resolution quantizer shape the noise spectrum, facilitating accurate A/D conversion on narrow-band input signals. This is extended to the quadrature, or complex, case if a complex filter - having complex-valued coefficients and thus not restricted to a symmetrical frequency response - is placed in a ΣΔ loop. The modulator performs a “complex” A/D conversion on the pair of analog inputs, that are in phase-quadrature, and it has two high-speed bit stream outputs: one represents the real output; the other the imaginary output. When combined, these outputs form a complex signal that accurately represents the complex input within a narrow frequency band. This quadrature modulator is useful in architectures for a single-chip digital-radio receiver. The receiver ideally has no image response, and thus the bulky narrow-band image-rejection filter in the RF stage of a single-path receiver can be replaced with a broadband one. The architecture alleviates many problems of the direct-conversion receiver, often considered for single-chip implementations, since the input signal is mixed to a non-zero IF where 1/f noise and DC offsets cause no problem and self-interference is not an issue because oscillator frequency is offset from the carrier frequency. The quadrature modulator IC uses standard fully-differential switched-capacitor circuit techniques and is implemented in 0.8 μm CMOS technology | H11: Jantzi, S.; Martin, K.; Sedra, A. | I11: 10.1109/ISSCC.1997.585339 | J11: =IF(I11<>"?", HYPERLINK(CONCATENATE("https://doi.org/",I11)), "") -> https://doi.org/10.1109/ISSCC.1997.585339 | K11: Data taken for max. BW, IF=3.75MHz | P11: 4.32 | R11: 200000 | S11: 62 | U11: 67 | X11: =+IF(ISNUMBER($S11),$S11,MIN($V11,$T11,$U11,$W11)) -> 62 | Y11: 0.13 | Z11: 10000000 | AA11: 25 | AB11: =Z11/AA11 -> 400000 | AC11: 3750000 | AD11: =Y11/AB11*1000000000000 -> 325000 | AE11: =IF(ISNUMBER($Q11), $AD11*1000/2^(($Q11-1.76)/6.02), "") | AF11: =$AD11*1000/2^(($X11-1.76)/6.02) -> 315924.43 | AG11: =IF(ISNUMBER($Q11), $Q11+10*LOG10($AB11/2/$Y11), "") | AH11: =$X11+10*LOG10($AB11/2/$Y11) -> 123.87087 | AI11: =AF11/AB11 -> 0.78981106 | AJ11: =AH11+10*LOG10(AB11) -> 179.89147
A12: 1997 | B12: 13.6 | C12: OS | D12: SDSC | E12: 0.8 | F12: A 5 V, 118 dB ΣΔ analog-to digital converter for wideband digital audio | G12: Digital signal processing can replace analog signal processing in professional audio equipment only when analog-to-digital converter dynamic ranges approach 120 dB. Super-high-end audio applications extend the audio band beyond 30 kHz and require 96 kHz sampling frequency. This paper describes a multi-bit ΣΔ modulator developed for high-end digital audio. The modulator is a single-loop, seventh-order type with a 3-level quantizer. The modulator samples the analog input at 6.144 MHz and has 140 dB signal-to-quantization noise in a 48 kHz bandwidth. The device is fabricated in a double-poly, double-metal, 0.8 μm CMOS process | H12: Leung, K.Y.; Swanson, E.J.; Kafai Leung; Zhu, S.S. | I12: 10.1109/ISSCC.1997.585340 | J12: =IF(I12<>"?", HYPERLINK(CONCATENATE("https://doi.org/",I12)), "") -> https://doi.org/10.1109/ISSCC.1997.585340 | P12: 25 | R12: 48000 | S12: 110 | U12: 118 | X12: =+IF(ISNUMBER($S12),$S12,MIN($V12,$T12,$U12,$W12)) -> 110 | Y12: 0.76 | Z12: 6144000 | AA12: 64 | AB12: =Z12/AA12 -> 96000 | AD12: =Y12/AB12*1000000000000 -> 7916666.7 | AE12: =IF(ISNUMBER($Q12), $AD12*1000/2^(($Q12-1.76)/6.02), "") | AF12: =$AD12*1000/2^(($X12-1.76)/6.02) -> 30619.848 | AG12: =IF(ISNUMBER($Q12), $Q12+10*LOG10($AB12/2/$Y12), "") | AH12: =$X12+10*LOG10($AB12/2/$Y12) -> 158.00428 | AI12: =AF12/AB12 -> 0.31895675 | AJ12: =AH12+10*LOG10(AB12) -> 207.82699
A13: 1997 | B13: 13.7 | C13: OS | D13: SDCT | E13: 0.5 | F13: A 2.3 mW CMOS ΣΔ modulator for audio applications | G13: This audio-quality CMOS ΣΔ modulator operates from a 3.3 V supply with 2.3 mW power consumption. The dynamic range is 96 dB over a 20-20000 Hz bandwidth and THD for a 1 kHz maximum input signal is -104 dB. A modulator with power consumption increased to 6.6 mW at the same supply voltage has 10l dB dynamic range and THD<-110 dB, proving the tradeoff between power consumption and performance | H13: van der Zwan, E.J. | I13: 10.1109/ISSCC.1997.585345 | J13: =IF(I13<>"?", HYPERLINK(CONCATENATE("https://doi.org/",I13)), "") -> https://doi.org/10.1109/ISSCC.1997.585345 | L13: 3.3 | P13: 0.4 | R13: 20000 | U13: 96 | V13: 104 | X13: =+IF(ISNUMBER($S13),$S13,MIN($V13,$T13,$U13,$W13)) -> 96 | Y13: 0.0023 | Z13: 5644800 | AA13: 141.12 | AB13: =Z13/AA13 -> 40000 | AD13: =Y13/AB13*1000000000000 -> 57500 | AE13: =IF(ISNUMBER($Q13), $AD13*1000/2^(($Q13-1.76)/6.02), "") | AF13: =$AD13*1000/2^(($X13-1.76)/6.02) -> 1114.8034 | AG13: =IF(ISNUMBER($Q13), $Q13+10*LOG10($AB13/2/$Y13), "") | AH13: =$X13+10*LOG10($AB13/2/$Y13) -> 165.39302 | AI13: =AF13/AB13 -> 0.027870085 | AJ13: =AH13+10*LOG10(AB13) -> 211.41362
A14: 1998 | B14: 4.4 | C14: OS | D14: SDSC | E14: 0.6 | F14: A 100 kHz 9.6 mW multi bit ΔΣ DAC and ADC using noise shaping dynamic elements matching with tree structure | G14: A multi-bit ΔΣ modulator (ΔΣM) is an attractive means for realizing a high-speed low-power data converter. A loss in dynamic range occurs if stabilization of the feedback loop for a higher-order DSM uses a 1b feedback signal. The classical 1b ADC and/or DAC do not follow the theoretical SNR of (8+6 N)L(dB), where N is the order of the DSM, and 2L is the oversampling ratio. In contrast, multi-bit feedback stabilizes a higher-order DSM with little loss of dynamic range. As the internal signal swing is reduced with increase in number of feedback signal bits, the multi-bit DSM requires a lower slew rate and thus less power for analog circuits than the 1b case. There is an increase in SNR due to use of a multi-bit internal DAC to reduce the oversampling ratio and hence to reduce power consumption of the analog portion | H14: Yasuda, A.; Tanimoto, H.; Lida, T. | I14: 10.1109/ISSCC.1998.672377 | J14: =IF(I14<>"?", HYPERLINK(CONCATENATE("https://doi.org/",I14)), "") -> https://doi.org/10.1109/ISSCC.1998.672377 | R14: 100000 | U14: 79 | V14: 75 | X14: =+IF(ISNUMBER($S14),$S14,MIN($V14,$T14,$U14,$W14)) -> 75 | Y14: 0.0096 | Z14: 5000000 | AA14: 25 | AB14: =Z14/AA14 -> 200000 | AD14: =Y14/AB14*1000000000000 -> 48000 | AE14: =IF(ISNUMBER($Q14), $AD14*1000/2^(($Q14-1.76)/6.02), "") | AF14: =$AD14*1000/2^(($X14-1.76)/6.02) -> 10444.227 | AG14: =IF(ISNUMBER($Q14), $Q14+10*LOG10($AB14/2/$Y14), "") | AH14: =$X14+10*LOG10($AB14/2/$Y14) -> 145.17729 | AI14: =AF14/AB14 -> 0.052221136 | AJ14: =AH14+10*LOG10(AB14) -> 198.18759
A15: 1998 | B15: 4.6 | C15: OS | D15: SDSC, SwOpAmp | E15: 0.5 | F15: A 900 mV 40 μW switched opamp ΔΣ modulator with 77 dB dynamic range | G15: Portable electronic systems require low-voltage low-power building blocks. An important building block is an A/D converter. ΔΣ ADCs provide an efficient way of trading off speed for resolution. The switched op amp (SO) technique allows design of switched-capacitor (SC) circuits at very low supply voltage without the use of multithreshold technologies or voltage multipliers to drive the switches. The basic idea of it is to leave out the switches connected to the output of the amplifier in a SC integrator, because those are the ones that fail to conduct when the supply voltage is low. Switches can only be connected to well-chosen reference voltages. In this implementation the differential modified SO integrator cell is used, so the reference voltages are VSS and VDD. This allows maximum overdrive of VDD-VSS for the switches | H15: Peluso, V.; Vancorenland, P.; Marques, A.; Steyaert, M.; Sansen, W. | I15: 10.1109/ISSCC.1998.672379 | J15: =IF(I15<>"?", HYPERLINK(CONCATENATE("https://doi.org/",I15)), "") -> https://doi.org/10.1109/ISSCC.1998.672379 | P15: 0.85 | R15: 16000 | S15: 62 | U15: 77 | X15: =+IF(ISNUMBER($S15),$S15,MIN($V15,$T15,$U15,$W15)) -> 62 | Y15: 4e-05 | Z15: 1538000 | AA15: 48.0625 | AB15: =Z15/AA15 -> 32000 | AD15: =Y15/AB15*1000000000000 -> 1250 | AE15: =IF(ISNUMBER($Q15), $AD15*1000/2^(($Q15-1.76)/6.02), "") | AF15: =$AD15*1000/2^(($X15-1.76)/6.02) -> 1215.0939 | AG15: =IF(ISNUMBER($Q15), $Q15+10*LOG10($AB15/2/$Y15), "") | AH15: =$X15+10*LOG10($AB15/2/$Y15) -> 148.0206 | AI15: =AF15/AB15 -> 0.037971686 | AJ15: =AH15+10*LOG10(AB15) -> 193.0721
A16: 1998 | B16: 9.1 | C16: NQ | D16: Pipe | E16: 0.7 | F16: A single-ended 12b 20Msample/s self-calibrating pipeline A/D converter | G16: This single-ended 12b 20 MSample/s pipeline ADC has good performance for Nyquist frequency inputs. Architecture and calibration algorithms minimize digital correction circuitry and noise crosstalk. The single-ended performance is achieved with a novel input common-mode feedback technique in the S/H stage. The total power dissipation is only 250 mW from a single 5 V supply | H16: I. Opris, L. Lewicki, and B. Wong | I16: 10.1109/ISSCC.1998.672406 | J16: =IF(I16<>"?", HYPERLINK(CONCATENATE("https://doi.org/",I16)), "") -> https://doi.org/10.1109/ISSCC.1998.672406 | L16: 5 | P16: 9 | R16: 10000000 | T16: 65.4 | V16: 70.6 | X16: =+IF(ISNUMBER($S16),$S16,MIN($V16,$T16,$U16,$W16)) -> 65.4 | Y16: 0.25 | Z16: 20000000 | AA16: 1 | AB16: =Z16/AA16 -> 20000000 | AD16: =Y16/AB16*1000000000000 -> 12500 | AE16: =IF(ISNUMBER($Q16), $AD16*1000/2^(($Q16-1.76)/6.02), "") | AF16: =$AD16*1000/2^(($X16-1.76)/6.02) -> 8214.7229 | AG16: =IF(ISNUMBER($Q16), $Q16+10*LOG10($AB16/2/$Y16), "") | AH16: =$X16+10*LOG10($AB16/2/$Y16) -> 141.4206 | AI16: =AF16/AB16 -> 0.00041073614 | AJ16: =AH16+10*LOG10(AB16) -> 214.4309
A17: 1998 | B17: 9.2 | C17: NQ | D17: Pipe, TI | E17: 1 | F17: Digital background calibration of a 10b 40Msample/s parallel pipelined ADC | G17: This time-interleaved pipelined ADC uses monolithic digital background calibration to overcome the effects of the offset and gain mismatches between channels. The contributions here are use of digital background calibration to overcome these mismatches and implementation of these techniques in conjunction with the ADCs on one CMOS IC. Background calibration is done by adding a calibration signal to the ADC input and processing both simultaneously. A potential advantage of this approach is that the calibration signal acts as dither and improves the linearity of the system | H17: D. Fu, K. Dyer, S. Lewis, and P. Hurst, | I17: 10.1109/ISSCC.1998.672407 | J17: =IF(I17<>"?", HYPERLINK(CONCATENATE("https://doi.org/",I17)), "") -> https://doi.org/10.1109/ISSCC.1998.672407 | P17: 22 | R17: 20000000 | S17: 55 | U17: 55 | W17: 72 | X17: =+IF(ISNUMBER($S17),$S17,MIN($V17,$T17,$U17,$W17)) -> 55 | Y17: 0.565 | Z17: 40000000 | AA17: 1 | AB17: =Z17/AA17 -> 40000000 | AD17: =Y17/AB17*1000000000000 -> 14125 | AE17: =IF(ISNUMBER($Q17), $AD17*1000/2^(($Q17-1.76)/6.02), "") | AF17: =$AD17*1000/2^(($X17-1.76)/6.02) -> 30741.367 | AG17: =IF(ISNUMBER($Q17), $Q17+10*LOG10($AB17/2/$Y17), "") | AH17: =$X17+10*LOG10($AB17/2/$Y17) -> 130.48982 | AI17: =AF17/AB17 -> 0.00076853418 | AJ17: =AH17+10*LOG10(AB17) -> 206.51042
A18: 1998 | B18: 9.3 | C18: NQ | D18: Pipe, TI | E18: 1 | F18: Analog background calibration of a 10b 40Msample/s parallel pipelined ADC | G18: The sampling rate of an ADC often limits speed of a signal processing system. Sampling rate at the A/D interface can be increased by using multiple component ADCs that are time interleaved. Mismatches in offsets, gains, and sampling times among the component ADCs limit the performance of the ADC system. Previous time-interleaved ADC arrays use careful layout, foreground calibration and/or digital filters to minimize the effects of these mismatches. The presented time-interleaved ADC uses monolithic analog background calibration to match the gains and offsets of the component pipelined ADCs. The contributions are an expandible adaptive background calibration technique for parallel ADCs and a calibration loop that uses a mixed-signal integrator. The fully-differential prototype is fabricated in a 1.0 μm CMOS single-poly process with poly-thin-oxide-diffusion capacitors. It includes 3 pipelined ADCs, one algorithmic ADC, the calibration signal generator, channel control logic, and 6 mixed-signal integrators, each followed by a unity-gain buffer that supplies the offset or reference correction voltage to one of the pipelined ADCs. The SC integrator and ADC stages use telescopic opamps with source followers at the input | H18: K. Dyer, D. Fu, S. Lewis, and P. Hurst, | I18: 10.1109/ISSCC.1998.672408 | J18: =IF(I18<>"?", HYPERLINK(CONCATENATE("https://doi.org/",I18)), "") -> https://doi.org/10.1109/ISSCC.1998.672408 | P18: 42 | R18: 20000000 | S18: 58 | X18: =+IF(ISNUMBER($S18),$S18,MIN($V18,$T18,$U18,$W18)) -> 58 | Y18: 0.65 | Z18: 40000000 | AA18: 1 | AB18: =Z18/AA18 -> 40000000 | AD18: =Y18/AB18*1000000000000 -> 16250 | AE18: =IF(ISNUMBER($Q18), $AD18*1000/2^(($Q18-1.76)/6.02), "") | AF18: =$AD18*1000/2^(($X18-1.76)/6.02) -> 25036.473 | AG18: =IF(ISNUMBER($Q18), $Q18+10*LOG10($AB18/2/$Y18), "") | AH18: =$X18+10*LOG10($AB18/2/$Y18) -> 132.88117 | AI18: =AF18/AB18 -> 0.00062591181 | AJ18: =AH18+10*LOG10(AB18) -> 208.90177
A19: 1998 | B19: 9.4 | C19: NQ | D19: Pipe | E19: 0.5 | F19: A continuously-calibrated 10Msample/s 12b 3.3V ADC | G19: Continuous calibration allows a converter to function continuously in the presence of environmental fluctuations and supply variations by periodically correcting for errors without interrupting the ADC output. This paper introduces a technique for continuously calibrating a pipelined A/D converter. Calibration is performed in the analog domain so as to avoid high-linearity calibration hardware or complex signal processing. A 10 MS ample/s, 12b converter implemented in a conventional 0.5 μm, single-poly, four-metal, CMOS technology operates from a 3.3V supply. This experimental circuit digitizes a 4.8 MHz signal with a peak SNDR of 67 dB | H19: Joseph Ingino Jr. and Bruce Wooley | I19: 10.1109/ISSCC.1998.672409 | J19: =IF(I19<>"?", HYPERLINK(CONCATENATE("https://doi.org/",I19)), "") -> https://doi.org/10.1109/ISSCC.1998.672409 | L19: 3.3 | P19: 14.5 | R19: 5000000 | S19: 67 | X19: =+IF(ISNUMBER($S19),$S19,MIN($V19,$T19,$U19,$W19)) -> 67 | Y19: 0.265 | Z19: 10000000 | AA19: 1 | AB19: =Z19/AA19 -> 10000000 | AD19: =Y19/AB19*1000000000000 -> 26500 | AE19: =IF(ISNUMBER($Q19), $AD19*1000/2^(($Q19-1.76)/6.02), "") | AF19: =$AD19*1000/2^(($X19-1.76)/6.02) -> 14485.077 | AG19: =IF(ISNUMBER($Q19), $Q19+10*LOG10($AB19/2/$Y19), "") | AH19: =$X19+10*LOG10($AB19/2/$Y19) -> 139.75724 | AI19: =AF19/AB19 -> 0.0014485077 | AJ19: =AH19+10*LOG10(AB19) -> 209.75724
A20: 1998 | B20: 9.5 | C20: NQ | D20: Pipe, TI | E20: 0.5 | F20: 8b 75Msample/s 70mW parallel pipelined ADC incorporating double sampling | G20: This 8b pipelined analog-to-digital converter (ADC) incorporates double sampling into the residue signal path of a 1.5b-per-stage architecture to effectively double the throughput of the ADC for a given analog power consumption. Residue amplifiers and sub-ADC comparators are shared between two time-interleaved channels and the sampling capacitors in the second stage are scaled in order to reduce power consumption. The ADC presented here achieves 75 MSamples/s while consuming 70 mW. The converter measures 5.5 mm² and is fabricated in a 3.3 V 0.5 μm digital CMOS process with four levels of metal and no special mask layers for passive components | H20: W. Bright | I20: 10.1109/ISSCC.1998.672410 | J20: =IF(I20<>"?", HYPERLINK(CONCATENATE("https://doi.org/",I20)), "") -> https://doi.org/10.1109/ISSCC.1998.672410 | P20: 5.5 | R20: 37500000 | S20: 43.3 | T20: 46.3 | U20: 47 | W20: 51 | X20: =+IF(ISNUMBER($S20),$S20,MIN($V20,$T20,$U20,$W20)) -> 43.3 | Y20: 0.07 | Z20: 75000000 | AA20: 1 | AB20: =Z20/AA20 -> 75000000 | AD20: =Y20/AB20*1000000000000 -> 933.33333 | AE20: =IF(ISNUMBER($Q20), $AD20*1000/2^(($Q20-1.76)/6.02), "") | AF20: =$AD20*1000/2^(($X20-1.76)/6.02) -> 7813.2154 | AG20: =IF(ISNUMBER($Q20), $Q20+10*LOG10($AB20/2/$Y20), "") | AH20: =$X20+10*LOG10($AB20/2/$Y20) -> 130.58933 | AI20: =AF20/AB20 -> 0.00010417621 | AJ20: =AH20+10*LOG10(AB20) -> 209.33994
A21: 1998 | B21: 9.6 | C21: NQ | D21: Flash | E21: 0.35 BiCMOS | F21: A 5.75b 350Msample/s or 6.75b 150Msample/s reconfigurable flash ADC for a PRML read channel | G21: A reconfigurable flash analog-to-digital converter (ADC), is suited for use in a partial response maximum likelihood (PRML) read channel with digital servo. A 5V version is integrated in a read channel with digital servo using BiCMOS technology | H21: P. Setty, J. Barner, J. Plany, H. Burger, and J. Sonntag | I21: 10.1109/ISSCC.1998.672411 | J21: =IF(I21<>"?", HYPERLINK(CONCATENATE("https://doi.org/",I21)), "") -> https://doi.org/10.1109/ISSCC.1998.672411 | P21: 0.75 | R21: 175000000 | S21: 31 | X21: =+IF(ISNUMBER($S21),$S21,MIN($V21,$T21,$U21,$W21)) -> 31 | Y21: 0.225 | Z21: 350000000 | AA21: 1 | AB21: =Z21/AA21 -> 350000000 | AD21: =Y21/AB21*1000000000000 -> 642.85714 | AE21: =IF(ISNUMBER($Q21), $AD21*1000/2^(($Q21-1.76)/6.02), "") | AF21: =$AD21*1000/2^(($X21-1.76)/6.02) -> 22180.37 | AG21: =IF(ISNUMBER($Q21), $Q21+10*LOG10($AB21/2/$Y21), "") | AH21: =$X21+10*LOG10($AB21/2/$Y21) -> 119.90856 | AI21: =AF21/AB21 -> 6.3372485e-05 | AJ21: =AH21+10*LOG10(AB21) -> 205.34924
A22: 1998 | B22: 9.7 | C22: NQ | D22: Folding | E22: 0.50 BiCMOS | F22: A 400Msample/s 6b CMOS folding and interpolating ADC | G22: A 6b 400 MSample/s folding and interpolating CMOS ADC uses a low-impedance current-mode approach. Current division interpolation in the folders allows fast low-voltage operation. This interpolation together with a short aperture comparator, gives good performance for high-frequency inputs, without using a sample-and-hold. The ADC uses a single clock and its complement. The 0.6 mm² CMOS converter, fabricated in a 0.5 μm BiCMOS process dissipates 200 mW from a 3.2 V supply | H22: M. Flynn, B. Sheahan | I22: 10.1109/ISSCC.1998.672412 | J22: =IF(I22<>"?", HYPERLINK(CONCATENATE("https://doi.org/",I22)), "") -> https://doi.org/10.1109/ISSCC.1998.672412 | L22: 3.2 | P22: 0.6 | R22: 200000000 | S22: 29.2 | V22: 33.6 | X22: =+IF(ISNUMBER($S22),$S22,MIN($V22,$T22,$U22,$W22)) -> 29.2 | Y22: 0.2 | Z22: 400000000 | AA22: 1 | AB22: =Z22/AA22 -> 400000000 | AD22: =Y22/AB22*1000000000000 -> 500 | AE22: =IF(ISNUMBER($Q22), $AD22*1000/2^(($Q22-1.76)/6.02), "") | AF22: =$AD22*1000/2^(($X22-1.76)/6.02) -> 21224.295 | AG22: =IF(ISNUMBER($Q22), $Q22+10*LOG10($AB22/2/$Y22), "") | AH22: =$X22+10*LOG10($AB22/2/$Y22) -> 119.2 | AI22: =AF22/AB22 -> 5.3060738e-05 | AJ22: =AH22+10*LOG10(AB22) -> 205.2206
A23: 1999 | B23: 3.1 | C23: OS | D23: SDSC | E23: 0.5 | F23: A 1.5 V 1.0 mW audio ΔΣ modulator with 98 dB dynamic range | G23: This audio-quality switched-capacitor (SC) ΔΣ modulator operates from a single 1.5 V supply and dissipates 1.0 mW. When clocked at 2.82 MHz, it achieves 98.2 dB dynamic range (DR) in a 20 kHz bandwidth. The peak SNR and SNDR are 90 dB and 88 dB, respectively. The fully-differential experimental circuit has been integrated in a 0.5 μm triple-metal single-poly CMOS n-well process with metal-to-poly capacitors. | H23: A.L. Coban, P.E. Allen | I23: 10.1109/ISSCC.1999.759091 | J23: =IF(I23<>"?", HYPERLINK(CONCATENATE("https://doi.org/",I23)), "") -> https://doi.org/10.1109/ISSCC.1999.759091 | L23: 1.5 | P23: 0.53 | R23: 20000 | S23: 88 | T23: 90 | U23: 98.2 | X23: =+IF(ISNUMBER($S23),$S23,MIN($V23,$T23,$U23,$W23)) -> 88 | Y23: =0.00067*1.5 -> 0.001005 | Z23: 2822400 | AA23: 70.56 | AB23: =Z23/AA23 -> 40000 | AD23: =Y23/AB23*1000000000000 -> 25125 | AE23: =IF(ISNUMBER($Q23), $AD23*1000/2^(($Q23-1.76)/6.02), "") | AF23: =$AD23*1000/2^(($X23-1.76)/6.02) -> 1223.704 | AG23: =IF(ISNUMBER($Q23), $Q23+10*LOG10($AB23/2/$Y23), "") | AH23: =$X23+10*LOG10($AB23/2/$Y23) -> 160.98864 | AI23: =AF23/AB23 -> 0.030592599 | AJ23: =AH23+10*LOG10(AB23) -> 207.00924
A24: 1999 | B24: 3.2 | C24: OS | D24: SDCT | E24: 0.35 | F24: A 1.8 mW CMOS ΣΔ modulator with integrated mixer for A/D conversion of IF signals | G24: This CMOS IFΣΔ modulator combines the functions of an IF mixer and an anti-aliasing filter with a continuous-time (CT) baseband ΣΔ modulator for A/D conversion of IF signals in radio receivers. Advantage is taken of the high linearity and low-power of the CT baseband ΣΔ modulator. The resulting IFΣΔ modulator consumes 1.8 mW and has +36 dBV IP3. The IF ΣΔ modulator of this paper is for mobile phones (GSM specification), and is promising for application in other types of receivers | H24: Breems, L.J.; van de Zwan, E.J.; Dijkmans, E.C.; Huijsing, J.H. | I24: 10.1109/ISSCC.1999.759363 | J24: =IF(I24<>"?", HYPERLINK(CONCATENATE("https://doi.org/",I24)), "") -> https://doi.org/10.1109/ISSCC.1999.759363 | P24: 0.2 | R24: 100000 | S24: 84 | U24: 86 | X24: =+IF(ISNUMBER($S24),$S24,MIN($V24,$T24,$U24,$W24)) -> 84 | Y24: 0.0018 | Z24: 13000000 | AA24: 65 | AB24: =Z24/AA24 -> 200000 | AD24: =Y24/AB24*1000000000000 -> 9000 | AE24: =IF(ISNUMBER($Q24), $AD24*1000/2^(($Q24-1.76)/6.02), "") | AF24: =$AD24*1000/2^(($X24-1.76)/6.02) -> 694.75669 | AG24: =IF(ISNUMBER($Q24), $Q24+10*LOG10($AB24/2/$Y24), "") | AH24: =$X24+10*LOG10($AB24/2/$Y24) -> 161.44727 | AI24: =AF24/AB24 -> 0.0034737834 | AJ24: =AH24+10*LOG10(AB24) -> 214.45757
A25: 1999 | B25: 3.3 | C25: OS | D25: SDSC, Pipe | E25: 1.2 | F25: A Nyquist-rate pipelined oversampling A/D converter | G25: Oversampling and noise-shaping techniques, such as ΣΔ modulation, have an inherent tradeoff between accuracy and speed, whereby resolution in amplitude is at the expense of resolution in time. Because their internal circuits must operate over many clock cycles to produce a single result, they have limited data rates and power dissipation is a concern. Much attention has been focused on improving the speed and power of ΣΔ analog-to-digital converters (ADCs) by use of higher-order modulators, multi-bit feedback, and multi-bit architectures with single-bit feedback. However, data rates remain limited to less than a few MHz and are not easily extended. A pipelined oversampling architecture circumvents this speed-resolution tradeoff by performing spatial, rather than temporal, oversampling. It combines the high resolution of Σδ techniques with the high speed of pipelined converters so that both of these attributes are simultaneously achievable | H25: Paul, S.; Hae-Seung Lee; Goodrich, J.; Alailima, T.; Santiago, D. | I25: 10.1109/ISSCC.1999.759092 | J25: =IF(I25<>"?", HYPERLINK(CONCATENATE("https://doi.org/",I25)), "") -> https://doi.org/10.1109/ISSCC.1999.759092 | P25: 47 | R25: 9000000 | S25: 71 | T25: 74 | U25: 78 | W25: 78 | X25: =+IF(ISNUMBER($S25),$S25,MIN($V25,$T25,$U25,$W25)) -> 71 | Y25: 0.324 | Z25: 18000000 | AA25: 1 | AB25: =Z25/AA25 -> 18000000 | AD25: =Y25/AB25*1000000000000 -> 18000 | AE25: =IF(ISNUMBER($Q25), $AD25*1000/2^(($Q25-1.76)/6.02), "") | AF25: =$AD25*1000/2^(($X25-1.76)/6.02) -> 6207.654 | AG25: =IF(ISNUMBER($Q25), $Q25+10*LOG10($AB25/2/$Y25), "") | AH25: =$X25+10*LOG10($AB25/2/$Y25) -> 145.43697 | AI25: =AF25/AB25 -> 0.00034486967 | AJ25: =AH25+10*LOG10(AB25) -> 217.9897
A26: 1999 | B26: 3.4 | C26: OS | D26: SDCT, BP | E26: 0.5 | F26: A 6th-order continuous-time bandpass ΣΔ modulator for digital radio IF | G26: A bandpass SD Modulator (SDM) ADC uses negative feedback of a bandpass-filtered error-signal and a high oversampling ratio to reduce the in-band errors of a low-resolution quantizer. As high-order (>4) bandpass SDMs exhibit signal-dependent stability, multibit quantizers are often used to lower the quantization noise of a 2nd or 4th order SDM. However, the accuracy required of the intermediate quantizer levels is high as mismatch affects the overall SDM performance. A 6th-order SDM has a single-bit quantizer for digitizing IF signals of 10.7 MHz | H26: van Engalen, J.; van de Plassche, R.; Sokvoort, E.; Venes, A. | I26: 10.1109/ISSCC.1999.759093 | J26: =IF(I26<>"?", HYPERLINK(CONCATENATE("https://doi.org/",I26)), "") -> https://doi.org/10.1109/ISSCC.1999.759093 | K26: Data for 10.7MHZ IF, BW=200kHz | P26: 0.36 | R26: 200000 | S26: 63.5 | U26: 67 | X26: =+IF(ISNUMBER($S26),$S26,MIN($V26,$T26,$U26,$W26)) -> 63.5 | Y26: 0.06 | Z26: 80000000 | AA26: 200 | AB26: =Z26/AA26 -> 400000 | AC26: 10700000 | AD26: =Y26/AB26*1000000000000 -> 150000 | AE26: =IF(ISNUMBER($Q26), $AD26*1000/2^(($Q26-1.76)/6.02), "") | AF26: =$AD26*1000/2^(($X26-1.76)/6.02) -> 122682.79 | AG26: =IF(ISNUMBER($Q26), $Q26+10*LOG10($AB26/2/$Y26), "") | AH26: =$X26+10*LOG10($AB26/2/$Y26) -> 128.72879 | AI26: =AF26/AB26 -> 0.30670696 | AJ26: =AH26+10*LOG10(AB26) -> 184.74939
A27: 1999 | B27: 3.7 | C27: OS | D27: SDCT | E27: 0.80 BiCMOS | F27: A 400 MHz 12 b 18 mW IF digitizer with mixer inside a ΣΔ modulator loop | G27: One method of IF digitization consists of a down-conversion mixer followed by a lowpass ΣΔ modulator. However, as one moves to high IF, the down conversion mixer's distortion deteriorates rapidly and more power has to be dissipated to restore the mixer's distortion to an acceptable level. In order to achieve low-distortion while maintaining low power dissipation, a new digitizer that suppresses this mixer distortion by placing the mixer inside a modified ΣΔ feedback loop, and capable of operating at 400 MHz, is presented | H27: Namdar, A.; Laung, B.H. | I27: 10.1109/ISSCC.1999.759096 | J27: =IF(I27<>"?", HYPERLINK(CONCATENATE("https://doi.org/",I27)), "") -> https://doi.org/10.1109/ISSCC.1999.759096 | P27: 1.5 | R27: 40000 | S27: 66 | U27: 72 | X27: =+IF(ISNUMBER($S27),$S27,MIN($V27,$T27,$U27,$W27)) -> 66 | Y27: 0.018 | Z27: 20000000 | AA27: 250 | AB27: =Z27/AA27 -> 80000 | AD27: =Y27/AB27*1000000000000 -> 225000 | AE27: =IF(ISNUMBER($Q27), $AD27*1000/2^(($Q27-1.76)/6.02), "") | AF27: =$AD27*1000/2^(($X27-1.76)/6.02) -> 137994.71 | AG27: =IF(ISNUMBER($Q27), $Q27+10*LOG10($AB27/2/$Y27), "") | AH27: =$X27+10*LOG10($AB27/2/$Y27) -> 129.46787 | AI27: =AF27/AB27 -> 1.7249338 | AJ27: =AH27+10*LOG10(AB27) -> 178.49877
A28: 1999 | B28: 18.1 | C28: NQ | D28: Algorithmic | E28: 1.5 | F28: A 12 b digital-background-calibrated algorithmic ADC with -90dB THD | G28: The linearity of analog-to-digital converters (ADCs) is often limited by component mismatches. Trimming can be used to achieve high linearity but cannot track variations over time caused by component aging or by temperature and power-supply changes. Background calibration overcomes this limitation. However, previous background-calibration methods require complicated post processing, occupy some of the range of the analog signal under conversion, or are tailored for a specific type of converter. This ADC uses a queue-based architecture for creating calibration time slots without disturbing the sampling of the input signal. The digital background calibration uses an adaptive algorithm to improve linearity. The queue-based architecture for generating the calibration time slots and the digital-background-calibration method are independent and can be used separately | H28: Ozan E. Erdogan, Paul J. Hurst, and Stephen H. Lewis | I28: 10.1109/ISSCC.1999.759266 | J28: =IF(I28<>"?", HYPERLINK(CONCATENATE("https://doi.org/",I28)), "") -> https://doi.org/10.1109/ISSCC.1999.759266 | P28: 5.94 | R28: 62500 | S28: 71 | V28: 90 | W28: 95 | X28: =+IF(ISNUMBER($S28),$S28,MIN($V28,$T28,$U28,$W28)) -> 71 | Y28: 0.016 | Z28: 125000 | AA28: 1 | AB28: =Z28/AA28 -> 125000 | AD28: =Y28/AB28*1000000000000 -> 128000 | AE28: =IF(ISNUMBER($Q28), $AD28*1000/2^(($Q28-1.76)/6.02), "") | AF28: =$AD28*1000/2^(($X28-1.76)/6.02) -> 44143.318 | AG28: =IF(ISNUMBER($Q28), $Q28+10*LOG10($AB28/2/$Y28), "") | AH28: =$X28+10*LOG10($AB28/2/$Y28) -> 136.9176 | AI28: =AF28/AB28 -> 0.35314654 | AJ28: =AH28+10*LOG10(AB28) -> 187.8867
A29: 1999 | B29: 18.2 | C29: NQ | D29: Two-Step | E29: 0.35 | F29: A 3.3V 10b 25Msample/s two-step ADC in 0.35µm CMOS | G29: System-on-chip for video, QAM and VSB applications requires analog-to-digital converters (ADC) in state-of-the-art CMOS technology. The untrimmed ADC is realized in standard single poly 0.35 μm CMOS technology with 3.3 V supply voltage, dissipates 195 mW and measures 0.8 mm², including track-and-hold and clock-generation circuits. This ADC achieves 9.3 ENOB with an effective resolution bandwidth of 14 MHz at 16 MSample/s sample frequency. The ADC is based on a two-step architecture, which combines a high sampling rate with a limited number of comparators. This ADC operates at 3.3 V supply voltage by using a floating ladder structure, full differential dual residue signal processing with improved switching and offset-compensated residue amplifiers. Latency is kept at a minimum of 2 cycles | H29: Hendrik van der Ploeg and Robert Remmers, | I29: 10.1109/ISSCC.1999.759267 | J29: =IF(I29<>"?", HYPERLINK(CONCATENATE("https://doi.org/",I29)), "") -> https://doi.org/10.1109/ISSCC.1999.759267 | K29: Fig. 18.2.6.a shows 7.8 ENOB at fin=12.5 MHz | L29: 3.3 | P29: 0.8 | R29: 12500000 | S29: =7.8*6.02+1.76 -> 48.716 | T29: 59.6 | V29: 62.8 | W29: 72 | X29: =+IF(ISNUMBER($S29),$S29,MIN($V29,$T29,$U29,$W29)) -> 48.716 | Y29: 0.195 | Z29: 25000000 | AA29: 1 | AB29: =Z29/AA29 -> 25000000 | AD29: =Y29/AB29*1000000000000 -> 7800 | AE29: =IF(ISNUMBER($Q29), $AD29*1000/2^(($Q29-1.76)/6.02), "") | AF29: =$AD29*1000/2^(($X29-1.76)/6.02) -> 34999.403 | AG29: =IF(ISNUMBER($Q29), $Q29+10*LOG10($AB29/2/$Y29), "") | AH29: =$X29+10*LOG10($AB29/2/$Y29) -> 126.78475 | AI29: =AF29/AB29 -> 0.0013999761 | AJ29: =AH29+10*LOG10(AB29) -> 200.76415
A30: 1999 | B30: 18.3 | C30: NQ | D30: Folding | E30: 0.60 BiCMOS | F30: A 65 mW 10 b 40 Msample/s BiCMOS Nyquist ADC in 0.8 mm 2 | G30: This ADC is to be embedded in video-signal-processing ICs. Because this integration is mixed-signal, focus during architectural and circuit design is on low power, low area consumption and low substrate noise sensitivity and generation. The 10 b ADC is based on a cascaded folding and interpolating architecture. Folding and interpolating factors are optimized for low power and low area. The circuit fully exploits the available 5 V supply by means of stacked folding topologies and dimensioning is based on balancing trade-off parameters for the various devices and stages. The untrimmed ADC achieves Nyquist performance at 40 MSample/s: the input frequency, where half an effective bit is lost compared to low input frequency performance, is 20 MHz. The low input frequency performance is 9.2 effective bits. The 0.8 mm² ADC is in 7 GHz, 0.6 μm BiCMOS and dissipates 65 mW from a single 5 V supply | H30: Gian Hoogzaad and Raf Roovers | I30: 10.1109/ISSCC.1999.759268 | J30: =IF(I30<>"?", HYPERLINK(CONCATENATE("https://doi.org/",I30)), "") -> https://doi.org/10.1109/ISSCC.1999.759268 | K30: Fig. 18.3.6.a shows 8.7 ENOB at fin=20 MHz | L30: 5 | P30: 0.8 | R30: 20000000 | S30: =8.7*6.02+1.76 -> 54.134 | T30: 59 | V30: 62 | W30: 67 | X30: =+IF(ISNUMBER($S30),$S30,MIN($V30,$T30,$U30,$W30)) -> 54.134 | Y30: 0.065 | Z30: 40000000 | AA30: 1 | AB30: =Z30/AA30 -> 40000000 | AD30: =Y30/AB30*1000000000000 -> 1625 | AE30: =IF(ISNUMBER($Q30), $AD30*1000/2^(($Q30-1.76)/6.02), "") | AF30: =$AD30*1000/2^(($X30-1.76)/6.02) -> 3907.4408 | AG30: =IF(ISNUMBER($Q30), $Q30+10*LOG10($AB30/2/$Y30), "") | AH30: =$X30+10*LOG10($AB30/2/$Y30) -> 139.01517 | AI30: =AF30/AB30 -> 9.7686019e-05 | AJ30: =AH30+10*LOG10(AB30) -> 215.03577
A31: 1999 | B31: 18.4 | C31: NQ | D31: Two-Step | E31: 0.5 | F31: A 75mW 10b 20MSample/s CMOS subranging ADC with 59dB SNDR | G31: In a two-step CMOS subranging ADC (CSA), a coarse comparator bank determines which subset of fine reference taps from a resistor ladder should be passed (without amplification or subtraction from the ADC input) to a fine comparator bank by an analog multiplexer (AMUX). This CSA provides advantages over previously-reported variations of this architecture. These advantages include absolute value signal processing, an extended settling period for the fine references, a fully differential topology, and a front-end sample-and-hold amplifier (SHA). As a result of these features, this ADC achieves 9.5 ENOB Nyquist performance at 75 mW and two-clock-cycle conversion latency | H31: Brian Brandt and Joseph Lutsky | I31: 10.1109/ISSCC.1999.759270 | J31: =IF(I31<>"?", HYPERLINK(CONCATENATE("https://doi.org/",I31)), "") -> https://doi.org/10.1109/ISSCC.1999.759270 | P31: 1.6 | R31: 10000000 | S31: 58.7 | T31: 60.5 | V31: 64 | W31: 64 | X31: =+IF(ISNUMBER($S31),$S31,MIN($V31,$T31,$U31,$W31)) -> 58.7 | Y31: 0.075 | Z31: 20000000 | AA31: 1 | AB31: =Z31/AA31 -> 20000000 | AD31: =Y31/AB31*1000000000000 -> 3750 | AE31: =IF(ISNUMBER($Q31), $AD31*1000/2^(($Q31-1.76)/6.02), "") | AF31: =$AD31*1000/2^(($X31-1.76)/6.02) -> 5330.2497 | AG31: =IF(ISNUMBER($Q31), $Q31+10*LOG10($AB31/2/$Y31), "") | AH31: =$X31+10*LOG10($AB31/2/$Y31) -> 139.94939 | AI31: =AF31/AB31 -> 0.00026651249 | AJ31: =AH31+10*LOG10(AB31) -> 212.95969
A32: 1999 | B32: 18.5 | C32: NQ | D32: Flash | E32: 0.4 | F32: A CMOS 6b 500MSample/s ADC for a hard disk drive read channel | G32: High-speed A/D converters (ADCs) are essential for improving the transfer rate of hard disk drives. This CMOS 6 b 500 MSample/s full-flash ADC for a read channel has 5.5 effective number of bits (ENOB) for a 125 MHz input signal (which is one quarter of the sampling rate). The ADC occupies 2.4 mm² and power consumption is 400 mW for a 3.3 V supply. 0.4 μm CMOS technology is used | H32: Yuko Tamba and Kazuo Yamakido | I32: 10.1109/ISSCC.1999.759272 | J32: =IF(I32<>"?", HYPERLINK(CONCATENATE("https://doi.org/",I32)), "") -> https://doi.org/10.1109/ISSCC.1999.759272 | L32: 3.3 | P32: 2.4 | R32: 250000000 | S32: =5.5*6.02+1.76 -> 34.87 | X32: =+IF(ISNUMBER($S32),$S32,MIN($V32,$T32,$U32,$W32)) -> 34.87 | Y32: 0.4 | Z32: 500000000 | AA32: 1 | AB32: =Z32/AA32 -> 500000000 | AD32: =Y32/AB32*1000000000000 -> 800 | AE32: =IF(ISNUMBER($Q32), $AD32*1000/2^(($Q32-1.76)/6.02), "") | AF32: =$AD32*1000/2^(($X32-1.76)/6.02) -> 17677.67 | AG32: =IF(ISNUMBER($Q32), $Q32+10*LOG10($AB32/2/$Y32), "") | AH32: =$X32+10*LOG10($AB32/2/$Y32) -> 122.8288 | AI32: =AF32/AB32 -> 3.5355339e-05 | AJ32: =AH32+10*LOG10(AB32) -> 209.8185
A33: 1999 | B33: 18.6 | C33: NQ | D33: Flash | E33: 0.6 | F33: A 6b 500MSample/s CMOS flash ADC with a background interpolated auto-zeroing technique | G33: A 6 b 500 MSample/s Flash ADC employs interpolated auto-zeroing carried out in background mode. To improve the ADC differential nonlinearity characteristic, a resistor network with its inherent error averaging property is employed for interpolation | H33: Kwangho Yoon, Sungkyung Park, and Wonchan Kim | I33: 10.1109/ISSCC.1999.759274 | J33: =IF(I33<>"?", HYPERLINK(CONCATENATE("https://doi.org/",I33)), "") -> https://doi.org/10.1109/ISSCC.1999.759274 | P33: 5.25 | Q33: 33.2 | R33: 100000000 | S33: 27.5 | X33: =+IF(ISNUMBER($S33),$S33,MIN($V33,$T33,$U33,$W33)) -> 27.5 | Y33: 0.33 | Z33: 500000000 | AA33: 1 | AB33: =Z33/AA33 -> 500000000 | AD33: =Y33/AB33*1000000000000 -> 660 | AE33: =IF(ISNUMBER($Q33), $AD33*1000/2^(($Q33-1.76)/6.02), "") -> 17676.134 | AF33: =$AD33*1000/2^(($X33-1.76)/6.02) -> 34073.416 | AG33: =IF(ISNUMBER($Q33), $Q33+10*LOG10($AB33/2/$Y33), "") -> 121.99426 | AH33: =$X33+10*LOG10($AB33/2/$Y33) -> 116.29426 | AI33: =AF33/AB33 -> 6.8146833e-05 | AJ33: =AH33+10*LOG10(AB33) -> 203.28396
A34: 2000 | B34: 2.1 | C34: NQ | D34: Folding | E34: Bipolar | F34: A 14b 100Msample/s 3-stage A/D converter | G34: A 14b three-stage ADC uses a complementary bipolar process to achieve a 100MSample/s encode rate with a SFDR of >90 dB and an SNR of 75 dB. While the design is based on a traditional multi-stage architecture, the three encoder stages use serial-ripple converters. Unlike the typical N-bit flash converter which requires 2-N-1 comparators, the serial-ripple converter has only N comparators. The result is a smaller die area and lower power dissipation than flash. This design uses a total of 16 comparators, and at the full sample rate consumes 1250 mW. It is fabricated in a 0.8 μm double-poly complementary bipolar process | H34: Carl Moreland, Michael Elliott, Frank Murden, Joe Young, Mike Hensley, and Russ Stop | I34: 10.1109/ISSCC.2000.839679 | J34: =IF(I34<>"?", HYPERLINK(CONCATENATE("https://doi.org/",I34)), "") -> https://doi.org/10.1109/ISSCC.2000.839679 | P34: 261 | R34: 50000000 | T34: 75 | X34: =+IF(ISNUMBER($S34),$S34,MIN($V34,$T34,$U34,$W34)) -> 75 | Y34: 1.25 | Z34: 100000000 | AA34: 1 | AB34: =Z34/AA34 -> 100000000 | AD34: =Y34/AB34*1000000000000 -> 12500 | AE34: =IF(ISNUMBER($Q34), $AD34*1000/2^(($Q34-1.76)/6.02), "") | AF34: =$AD34*1000/2^(($X34-1.76)/6.02) -> 2719.8508 | AG34: =IF(ISNUMBER($Q34), $Q34+10*LOG10($AB34/2/$Y34), "") | AH34: =$X34+10*LOG10($AB34/2/$Y34) -> 151.0206 | AI34: =AF34/AB34 -> 2.7198508e-05 | AJ34: =AH34+10*LOG10(AB34) -> 231.0206
A35: 2000 | B35: 2.2 | C35: NQ | D35: Folding | E35: 0.5 | F35: A 13b 40Msample/s CMOS pipelined folding ADC with background offset trimming | G35: The folding/interpolating ADC exhibits a distinct trait attributed by folder zero-crossing error and gain mismatch, which appear in general as an INL error. It is of paramount interest to control the zero-crossings accurately so that they can be spaced evenly to cover the whole conversion range. The folder zero-crossing errors collectively result from folder offset, reference error, tail-current mismatch, interpolation error, etc. In CMOS, the poor offset of the differential pair as well as other process uncertainty have resulted in the performance much poorer than the bipolar counterpart. This CMOS folding/interpolating ADC operates with 13 b linearity at bipolar folder speed | H35: Myung-Jun Choe, Bang-Sup Song, and Kantilal Bacrania, | I35: 10.1109/ISSCC.2000.839680 | J35: =IF(I35<>"?", HYPERLINK(CONCATENATE("https://doi.org/",I35)), "") -> https://doi.org/10.1109/ISSCC.2000.839680 | P35: 8.7 | R35: 20000000 | T35: 66 | W35: 82 | X35: =+IF(ISNUMBER($S35),$S35,MIN($V35,$T35,$U35,$W35)) -> 66 | Y35: 0.8 | Z35: 40000000 | AA35: 1 | AB35: =Z35/AA35 -> 40000000 | AD35: =Y35/AB35*1000000000000 -> 20000 | AE35: =IF(ISNUMBER($Q35), $AD35*1000/2^(($Q35-1.76)/6.02), "") | AF35: =$AD35*1000/2^(($X35-1.76)/6.02) -> 12266.196 | AG35: =IF(ISNUMBER($Q35), $Q35+10*LOG10($AB35/2/$Y35), "") | AH35: =$X35+10*LOG10($AB35/2/$Y35) -> 139.9794 | AI35: =AF35/AB35 -> 0.00030665491 | AJ35: =AH35+10*LOG10(AB35) -> 216
A36: 2000 | B36: 2.3 | C36: NQ | D36: Pipe | E36: 0.5 | F36: A 12b 65Msample/s CMOS ADC with 82dB SFDR at 120MHz | G36: A recent trend in cellular basestation design is to digitize multiple channels with a single ADC, often at the intermediate frequency (IF). This requires an ADC with wide dynamic range, particularly SFDR above 80 dB and SNR better than 70 dB, even when sampling input frequencies above 70 MHz. This 12b, 65MSample/s (MSPS) ADC incorporates a wide-bandwidth, low-distortion input stage coupled with a digitally-calibrated, multibit pipeline architecture optimized for low power consumption | H36: Larry Singer, Stacy Ho, Mike Timko, and Dan Kelly | I36: 10.1109/ISSCC.2000.839681 | J36: =IF(I36<>"?", HYPERLINK(CONCATENATE("https://doi.org/",I36)), "") -> https://doi.org/10.1109/ISSCC.2000.839681 | P36: 10 | R36: 32500000 | S36: 70 | T36: 70 | X36: =+IF(ISNUMBER($S36),$S36,MIN($V36,$T36,$U36,$W36)) -> 70 | Y36: 0.43 | Z36: 65000000 | AA36: 1 | AB36: =Z36/AA36 -> 65000000 | AD36: =Y36/AB36*1000000000000 -> 6615.3846 | AE36: =IF(ISNUMBER($Q36), $AD36*1000/2^(($Q36-1.76)/6.02), "") | AF36: =$AD36*1000/2^(($X36-1.76)/6.02) -> 2559.8533 | AG36: =IF(ISNUMBER($Q36), $Q36+10*LOG10($AB36/2/$Y36), "") | AH36: =$X36+10*LOG10($AB36/2/$Y36) -> 148.78415 | AI36: =AF36/AB36 -> 3.9382359e-05 | AJ36: =AH36+10*LOG10(AB36) -> 226.91328
